Workbook

Sheet Summary
A1: Hindi ASR Evaluation — Summary
A2: Generated: 2026-05-20 17:41:08 | D2: Total audios: | E2: =COUNTA('Evaluation'!A2:A351)
A4: Per-Method Accuracy Statistics
A5: Method | B5: Average % | C5: Min % | D5: Max % | E5: Std Dev %
A6: Script | B6: =IFERROR(ROUND(AVERAGE('Evaluation'!G2:G351),2),0) | C6: =IFERROR(MIN('Evaluation'!G2:G351),0) | D6: =IFERROR(MAX('Evaluation'!G2:G351),0) | E6: =IFERROR(ROUND(STDEV('Evaluation'!G2:G351),2),0)
A7: LLM | B7: =IFERROR(ROUND(AVERAGE('Evaluation'!H2:H351),2),0) | C7: =IFERROR(MIN('Evaluation'!H2:H351),0) | D7: =IFERROR(MAX('Evaluation'!H2:H351),0) | E7: =IFERROR(ROUND(STDEV('Evaluation'!H2:H351),2),0)
A9: Best-Performing Method (by average accuracy)
A10: Winner: | B10: =IF(B6>=B7,"Script","LLM") | C10: Best average: | D10: =MAX(B6,B7)
A12: Best & Worst Sample per Method
A13: Method | B13: Best Sample | C13: Best % | D13: Worst Sample | E13: Worst %
A14: Script | B14: =IFERROR(INDEX('Evaluation'!A2:A351,MATCH(MAX('Evaluation'!G2:G351),'Evaluation'!G2:G351,0)),"") | C14: =IFERROR(MAX('Evaluation'!G2:G351),0) | D14: =IFERROR(INDEX('Evaluation'!A2:A351,MATCH(MIN('Evaluation'!G2:G351),'Evaluation'!G2:G351,0)),"") | E14: =IFERROR(MIN('Evaluation'!G2:G351),0)
A15: LLM | B15: =IFERROR(INDEX('Evaluation'!A2:A351,MATCH(MAX('Evaluation'!H2:H351),'Evaluation'!H2:H351,0)),"") | C15: =IFERROR(MAX('Evaluation'!H2:H351),0) | D15: =IFERROR(INDEX('Evaluation'!A2:A351,MATCH(MIN('Evaluation'!H2:H351),'Evaluation'!H2:H351,0)),"") | E15: =IFERROR(MIN('Evaluation'!H2:H351),0)
A17: Mismatch Volume (rows with at least one mismatch)
A18: Method | B18: Rows With Mismatches | C18: % of Total
A19: Script | B19: =COUNTIF('Evaluation'!I2:I351,"?*") | C19: =IFERROR(ROUND(COUNTIF('Evaluation'!I2:I351,"?*")/COUNTA('Evaluation'!A2:A351)*100,2),0)
A20: LLM | B20: =COUNTIF('Evaluation'!J2:J351,"?*") | C20: =IFERROR(ROUND(COUNTIF('Evaluation'!J2:J351,"?*")/COUNTA('Evaluation'!A2:A351)*100,2),0)
A23: Methodology
A24: Benchmark column (C): Urdu Nastaliq → Roman Urdu via the rule-based
A25: urdu_to_roman_urdu script at the project root.
A26: 4-layer pipeline: word-level direct lookup (data/lexicons.json → urdu_direct)
A27: → per-character phonemic map with default short-vowel insertion
A28: → word-ending normalisation → shared CORRECTIONS lexicon.
A29: Deterministic, offline, editable by adding entries to data/lexicons.json.
A30: Methods scored against the benchmark:
A31: • Script (col E): hindi_to_roman_urdu.transliterate on the Hindi ASR output.
A32: • LLM (col F): Ollama Qwen3 transliteration of the Hindi ASR output.
A33: Accuracy: fuzzy word-level match against the script benchmark (col C).
A34: Tokens within 70% character-similarity count as matches.
... A36: the corresponding Roman ASR cells (cols E/F).

Sheet Evaluation
A1: Audio File Name | B1: Benchmark Urdu (Nastaliq) | C1: Benchmark Roman Urdu (script) | D1: Hindi ASR (Devanagari) | E1: Roman ASR — Script method | F1: Roman ASR — LLM method | G1: Accuracy % — Script | H1: Accuracy % — LLM | I1: Mismatched — Script | J1: Mismatched — LLM | K1: ASR Time (s) | L1: Status / Notes | M1: h_matched_script | N1: h_total_script | O1: h_matched_llm | P1: h_total_llm
A2: common_voice_ur_31771683.wav | B2: کبھی کبھار ہی خیالی پلاو بناتا ہوں | C2: kabhi kabhaar hi khayali pulao banata hoon | D2: कभी कबार ही ख़ैयाली प्लाव बनाता हूँ | E2: kabhi kabaar hi khaiyali plaaw banata hoon | G2: =IFERROR(ROUND(M2/N2*100,2),0) | H2: =IFERROR(ROUND(O2/P2*100,2),0) | I2: plaaw | K2: 6.55 | L2: ok | M2: 6 | N2: 7 | O2: 0 | P2: 0
A3: common_voice_ur_31771684.wav | B3: اور پھر ممکن ہے کہ پاکستان بھی ہو | C3: aur phir mumkin hai ke Pakistan bhi ho | D3: और फिर मुमकिन है कि पाकिस्तान भी हो। | E3: aur phir mumakin hai ki Pakistan bhi ho. | G3: =IFERROR(ROUND(M3/N3*100,2),0) | H3: =IFERROR(ROUND(O3/P3*100,2),0) | I3: ki | K3: 3.53 | L3: ok | M3: 7 | N3: 8 | O3: 0 | P3: 0
A4: common_voice_ur_31771685.wav | B4: یہ فیصلہ بھی گزشتہ دو سال میں | C4: yeh faisla bhi guzashta do saal mein | D4: ये फैसला भी गुजरिशता दो साल में | E4: yeh faisla bhi gujarishta do saal mein | G4: =IFERROR(ROUND(M4/N4*100,2),0) | H4: =IFERROR(ROUND(O4/P4*100,2),0) | K4: 4.68 | L4: ok | M4: 7 | N4: 7 | O4: 0 | P4: 0
A5: common_voice_ur_31771730.wav | B5: ان کے بلے بازوں کے سامنے ہو گا | C5: in ke bale baazon ke saamane ho ga | D5: इनके बले बाजू के सामने होगा। | E5: inke bale baajoo ke saamne hoga. | G5: =IFERROR(ROUND(M5/N5*100,2),0) | H5: =IFERROR(ROUND(O5/P5*100,2),0) | I5: inke, bale, baajoo, hoga | K5: 3.8 | L5: ok | M5: 2 | N5: 8 | O5: 0 | P5: 0
A6: common_voice_ur_31771732.wav | B6: آبی جانور میں بطخ بگلا اور دُوسْرا آبی پرندہ شامل ہونا | C6: aabi jaanor mein batakh bagala aur duosra aabi parnada shaamal hona | D6: आबी जानवर में बतख, भलगा और दूसरा आबी परिंदा शामिल होना। | E6: aabi jaanawar mein batakh, bhalga aur doosra aabi parinda shaamil hona. | G6: =IFERROR(ROUND(M6/N6*100,2),0) | H6: =IFERROR(ROUND(O6/P6*100,2),0) | I6: bhalga | K6: 7.76 | L6: ok | M6: 10 | N6: 11 | O6: 0 | P6: 0
A7: common_voice_ur_31771880.wav | B7: اِس طےشدہ مدت میں میرے ذمے پڑھانے کا کام کافی ہلکا ہے | C7: is teshda madat mein mire zame parhane ka kaam kafi halaka hai | D7: इस्तेशुदा मुद्दे में मेरे जिम्मे पढ़ाने का काम काफी हल्का है। | E7: isteshuda mudde mein mere jimme parhane ka kaam kaaphi halka hai. | G7: =IFERROR(ROUND(M7/N7*100,2),0) | H7: =IFERROR(ROUND(O7/P7*100,2),0) | I7: mudde, jimme, kaaphi | K7: 3.89 | L7: ok | M7: 8 | N7: 12 | O7: 0 | P7: 0
A8: common_voice_ur_31771882.wav | B8: فلمیں دیکھنی ہوں۔ | C8: filmein dikhani hoon. | D8: फिल्में देखनी हो। | E8: philmen dekhni ho. | G8: =IFERROR(ROUND(M8/N8*100,2),0) | H8: =IFERROR(ROUND(O8/P8*100,2),0) | I8: ho | K8: 2.98 | L8: ok | M8: 2 | N8: 3 | O8: 0 | P8: 0
A9: common_voice_ur_31771884.wav | B9: دوسرا اس وجہ سے کہ اس کی پشت پر ذرائع ابلاغ ہیں۔ | C9: dosara is wajah se ke is ki pashat par zraai ablaagh hain. | D9: दूसरा इस वजह से के इसकी पुष्ट पर जराए अबालगा हैं। | E9: doosra is wajah se ke iski pusht par jaraae abaalga hain. | G9: =IFERROR(ROUND(M9/N9*100,2),0) | H9: =IFERROR(ROUND(O9/P9*100,2),0) | I9: iski, jaraae | K9: 3.68 | L9: ok | M9: 9 | N9: 12 | O9: 0 | P9: 0
A10: common_voice_ur_31771885.wav | B10: اسکے معانی پر اور مفہوم پر کبھی غورکیا بھی نہیں | C10: asake mani par aur mafhom par kabhi ghorakiaa bhi nahi | D10: इसके माइनी पर और मफ़ोम पर कभी घोर किया भी नहीं। | E10: iske maaini par aur mafom par kabhi ghor kiya bhi nahi. | G10: =IFERROR(ROUND(M10/N10*100,2),0) | H10: =IFERROR(ROUND(O10/P10*100,2),0) | I10: iske, ghor, kiya | K10: 3.7 | L10: ok | M10: 8 | N10: 10 | O10: 0 | P10: 0
A11: common_voice_ur_31771886.wav | B11: ماتحت عدالتیں کس خوف کا شکار تھیں؟ | C11: maathat daalatin kis khauf ka shikar thin? | D11: मातृत्व अदालतें किस खौफ का शिकार थीं? | E11: maatritw adaalaten kis khauph ka shikaar thin? | G11: =IFERROR(ROUND(M11/N11*100,2),0) | H11: =IFERROR(ROUND(O11/P11*100,2),0) | I11: maatritw | K11: 3.44 | L11: ok | M11: 6 | N11: 7 | O11: 0 | P11: 0
A12: common_voice_ur_31772051.wav | B12: پانی کی ایک عجیب خاصیت تھی | C12: pani ki aik ajeeb khasiyat thi | D12: पानी की एक अजीब खासियत थी। | E12: pani ki ek ajeeb khaasiyat thi. | G12: =IFERROR(ROUND(M12/N12*100,2),0) | H12: =IFERROR(ROUND(O12/P12*100,2),0) | I12: ek | K12: 6.79 | L12: ok | M12: 5 | N12: 6 | O12: 0 | P12: 0
A13: common_voice_ur_31776227.wav | B13: چیئرمین پیس بی کی نیوزی لینڈ کو دورہ پاکستان کی پیشکش | C13: chairman pis B ki New Zealand ko daura Pakistan ki peshkash | D13: चेयरमैन पीसीबी की न्यूजीलैंड को दौरे पाकिस्तान की पेशकश | E13: cheyaramain peeseebi ki nyoojeelaind ko daure Pakistan ki peshakash | G13: =IFERROR(ROUND(M13/N13*100,2),0) | H13: =IFERROR(ROUND(O13/P13*100,2),0) | I13: cheyaramain, peeseebi, nyoojeelaind | K13: 3.75 | L13: ok | M13: 6 | N13: 11 | O13: 0 | P13: 0
A14: common_voice_ur_31776229.wav | B14: سمیت پاکستان کے تمام بڑے شہروں کے | C14: samit Pakistan ke tmaam bare shaharon ke | D14: समेत पाकिस्तान के तमाम बड़े शहरों के | E14: samet Pakistan ke tamaam bare shaharon ke | G14: =IFERROR(ROUND(M14/N14*100,2),0) | H14: =IFERROR(ROUND(O14/P14*100,2),0) | K14: 3.28 | L14: ok | M14: 7 | N14: 7 | O14: 0 | P14: 0
A15: common_voice_ur_31776231.wav | B15: جو یَہاں کا جنگلات کےحسن کو چار چاند لگنا دینا ہونا | C15: jo yhaan ka janglaat kehsan ko char chaanad lagana dina hona | D15: जो यहाँ के जंगलात के हुसन को चांद चांद लगना देना होना। | E15: jo yahan ke jangalaat ke husan ko chand chand lagna dena hona. | G15: =IFERROR(ROUND(M15/N15*100,2),0) | H15: =IFERROR(ROUND(O15/P15*100,2),0) | I15: ke, ke, chand | K15: 3.81 | L15: ok | M15: 9 | N15: 11 | O15: 0 | P15: 0
A16: common_voice_ur_31776296.wav | B16: فلم اچھا بزنس نہ کرتی ہو۔ | C16: film achha baznas na karti ho. | D16: फिल्म अच्छा बिजनेस ना करती हो। | E16: film acha bijanes na karti ho. | G16: =IFERROR(ROUND(M16/N16*100,2),0) | H16: =IFERROR(ROUND(O16/P16*100,2),0) | I16: bijanes | K16: 3.23 | L16: ok | M16: 5 | N16: 6 | O16: 0 | P16: 0
A17: common_voice_ur_31776298.wav | B17: صرف کام کرو کھانا کھاؤ ٹیکس دو کام ختم اور ہم بھی فارخ | C17: saraf kaam karo khana khaao tikas do kaam khatam aur hum bhi faarakh | D17: सिर्फ़ काम करो, खाना खाओ, टैक्स दो, काम खत्म और हम भी फारम | E17: sirf kaam karo, khana khao, tax do, kaam khatm aur hum bhi phaaram | G17: =IFERROR(ROUND(M17/N17*100,2),0) | H17: =IFERROR(ROUND(O17/P17*100,2),0) | I17: sirf, tax, phaaram | K17: 4.09 | L17: ok | M17: 10 | N17: 13 | O17: 0 | P17: 0
A18: common_voice_ur_31776299.wav | B18: ٹیلنٹ خاک ہے۔ | C18: tilnat khaak hai. | D18: टैलेंट खाक है। | E18: tailent khaak hai. | G18: =IFERROR(ROUND(M18/N18*100,2),0) | H18: =IFERROR(ROUND(O18/P18*100,2),0) | K18: 5.36 | L18: ok | M18: 3 | N18: 3 | O18: 0 | P18: 0
A19: common_voice_ur_31776428.wav | B19: فیفا ورلڈ کپ پیرو نے اسٹریلیا کو شکست دیدی | C19: fifa orlad kap piro ne astariliaa ko shaksat didi | D19: फ़िफ़ा वर्ल्ड कप पीरो ने ऑस्ट्रेलिया को शिकस्त दे दी। | E19: fifa warld kap peero ne Australia ko shikast de D. | G19: =IFERROR(ROUND(M19/N19*100,2),0) | H19: =IFERROR(ROUND(O19/P19*100,2),0) | I19: warld, peero, de, d | K19: 5.11 | L19: ok | M19: 6 | N19: 9 | O19: 0 | P19: 0
A20: common_voice_ur_31776429.wav | B20: کچھ بھِی ممکن ہے نیو گِنی فنڈ کے متعلق کِیا خیال ہے | C20: kachh bhi mumkin hai nio gini fanad ke matlaq kya khayal hai | D20: कुछ भी मुमकिन है न्यूजीलैंड फंड के मुताबिक क्या ख्याल है? | E20: kuch bhi mumakin hai nyoojeelaind phand ke mutaabik kya khyaal hai? | G20: =IFERROR(ROUND(M20/N20*100,2),0) | H20: =IFERROR(ROUND(O20/P20*100,2),0) | I20: kuch, nyoojeelaind, phand, mutaabik | K20: 4.1 | L20: ok | M20: 7 | N20: 12 | O20: 0 | P20: 0
A21: common_voice_ur_31776430.wav | B21: اچھی حکومت وہی ہے جو اس کا موقع کم آنے دیتی ہے۔ | C21: achhi hakomat ohi hai jo is ka moqa kam aane diti hai. | D21: अच्छी अकोमत वही है जो इसका मौका काम आने देती है। | E21: achchi akomat wahi hai jo iska mauka kaam aane deti hai. | G21: =IFERROR(ROUND(M21/N21*100,2),0) | H21: =IFERROR(ROUND(O21/P21*100,2),0) | I21: wahi, iska, mauka | K21: 3.4 | L21: ok | M21: 8 | N21: 12 | O21: 0 | P21: 0
A22: common_voice_ur_31776431.wav | B22: میرا کہنا یہ تھا کہ ٹاک شو میں اصلا دو فریق ہیں۔ | C22: mera kehna yeh tha ke taak sho mein asala do fariq hain. | D22: मेरा कहना ये था कि टॉक शो में असला दो फरीक हैं। | E22: mera kehna yeh tha ki tok sho mein asla do phareek hain. | G22: =IFERROR(ROUND(M22/N22*100,2),0) | H22: =IFERROR(ROUND(O22/P22*100,2),0) | I22: ki, tok, phareek | K22: 3.38 | L22: ok | M22: 9 | N22: 12 | O22: 0 | P22: 0
A23: common_voice_ur_31776466.wav | B23: اس وقت فلائنگ کوچ کی سیٹ پر بیٹھے ہوئے | C23: is waqt flaainag koch ki sit par bithe hoie | D23: इस वक़त फ्लाइंग कोच की सीट पर बैठे हुए | E23: is waqt phlaaing koch ki seat par baithe hue | G23: =IFERROR(ROUND(M23/N23*100,2),0) | H23: =IFERROR(ROUND(O23/P23*100,2),0) | I23: seat, hue | K23: 3.31 | L23: ok | M23: 7 | N23: 9 | O23: 0 | P23: 0
A24: common_voice_ur_31776469.wav | B24: ملک ایک بار پھر دو جماعتی نظام کی طرف لوٹ گیا ہے۔ | C24: malak aik baar phir do jamati nzaam ki taraf lot gaya hai. | D24: मुल्क के एक बार फिर दो जमाती नजाम की तरफ लौट गया है। | E24: mulk ke ek baar phir do jamati najaam ki taraph laut gaya hai. | G24: =IFERROR(ROUND(M24/N24*100,2),0) | H24: =IFERROR(ROUND(O24/P24*100,2),0) | I24: mulk, ke, ek, laut | K24: 3.51 | L24: ok | M24: 9 | N24: 12 | O24: 0 | P24: 0
A25: common_voice_ur_31776595.wav | B25: وہ بیساکھیوں کے سہارے چل رہی ہے۔ | C25: woh bisaakhion ke sahare chal rahi hai. | D25: वो बासाकियों के सहारे चल रही है। | E25: woh baasaakiyon ke sahare chal rahi hai. | G25: =IFERROR(ROUND(M25/N25*100,2),0) | H25: =IFERROR(ROUND(O25/P25*100,2),0) | K25: 3.17 | L25: ok | M25: 7 | N25: 7 | O25: 0 | P25: 0
A26: common_voice_ur_31776598.wav | B26: پاکستان میں اسما | C26: Pakistan mein asama | D26: پاکستان می‌آسما. | E26: پاکستان می‌آسما. | G26: =IFERROR(ROUND(M26/N26*100,2),0) | H26: =IFERROR(ROUND(O26/P26*100,2),0) | I26: پاکستان, می‌آسما | K26: 2.94 | L26: ok | M26: 0 | N26: 3 | O26: 0 | P26: 0
A27: common_voice_ur_31777458.wav | B27: یہ بات اب عیاں ہے۔ | C27: yeh baat ab iaan hai. | D27: ये बात अब आया है। | E27: yeh baat ab aaya hai. | G27: =IFERROR(ROUND(M27/N27*100,2),0) | H27: =IFERROR(ROUND(O27/P27*100,2),0) | I27: aaya | K27: 2.8 | L27: ok | M27: 4 | N27: 5 | O27: 0 | P27: 0
A28: common_voice_ur_31777462.wav | B28: اب وقت گزر چکا ہے۔ | C28: ab waqt gazar chaka hai. | D28: अब वक्त गुजर चुका है। | E28: ab waqt gujar chuka hai. | G28: =IFERROR(ROUND(M28/N28*100,2),0) | H28: =IFERROR(ROUND(O28/P28*100,2),0) | I28: gujar | K28: 3.16 | L28: ok | M28: 4 | N28: 5 | O28: 0 | P28: 0
A29: common_voice_ur_31784922.wav | B29: نہ اخبار میں بیان چھپواتے ہیں۔ | C29: na akhbaar mein biaan chhapoaate hain. | D29: ना अखबार में बयान चपवाते हैं। | E29: na akhabaar mein bayaan chapawate hain. | G29: =IFERROR(ROUND(M29/N29*100,2),0) | H29: =IFERROR(ROUND(O29/P29*100,2),0) | K29: 4.03 | L29: ok | M29: 6 | N29: 6 | O29: 0 | P29: 0
A30: common_voice_ur_31784923.wav | B30: جنہیں دوسرے ٹیسٹ کی شکست نے برہنہ کر کے رکھ دیا ہے | C30: janahin dosare test ki shaksat ne barhana kar ke rakh diya hai | D30: जिन्हें दूसरे टेस्ट की शक्सेस ने बलहीना करके रख दिया है। | E30: jinhen doosre test ki shakses ne balaheena karke rakh diya hai. | G30: =IFERROR(ROUND(M30/N30*100,2),0) | H30: =IFERROR(ROUND(O30/P30*100,2),0) | I30: jinhen, balaheena | K30: 4.19 | L30: ok | M30: 9 | N30: 12 | O30: 0 | P30: 0
A31: common_voice_ur_31784924.wav | B31: اس موقع سے وہ کیا فائدہ اٹھاتا ہے۔ | C31: is moqa se woh kya faaida athata hai. | D31: इस मौका से वो क्या फायदा उठाता है? | E31: is mauka se woh kya phaayda uthata hai? | G31: =IFERROR(ROUND(M31/N31*100,2),0) | H31: =IFERROR(ROUND(O31/P31*100,2),0) | I31: mauka, phaayda | K31: 3.32 | L31: ok | M31: 6 | N31: 8 | O31: 0 | P31: 0
A32: common_voice_ur_31784926.wav | B32: میں مجبور ہو گیا تھا | C32: mein majabor ho gaya tha | D32: मैं मजबूर हो गया था। | E32: main majaboor ho gaya tha. | G32: =IFERROR(ROUND(M32/N32*100,2),0) | H32: =IFERROR(ROUND(O32/P32*100,2),0) | K32: 2.96 | L32: ok | M32: 5 | N32: 5 | O32: 0 | P32: 0
A33: common_voice_ur_31784928.wav | B33: کہ فلم نے ریلیز کے پہلے روز آٹھ کروڑ، | C33: ke film ne riliz ke pehle roz aath crore, | D33: के फिल्म ने रिलीज के पहले रोज आठ करोड़ | E33: ke film ne rileej ke pahle roj aath crore | G33: =IFERROR(ROUND(M33/N33*100,2),0) | H33: =IFERROR(ROUND(O33/P33*100,2),0) | I33: rileej, roj | K33: 4.17 | L33: ok | M33: 7 | N33: 9 | O33: 0 | P33: 0
A34: common_voice_ur_31784929.wav | B34: تو دیکھیے گا۔ | C34: to dikhie ga. | D34: तो देखेगा | E34: to dekhega | G34: =IFERROR(ROUND(M34/N34*100,2),0) | H34: =IFERROR(ROUND(O34/P34*100,2),0) | I34: dekhega | K34: 2.7 | L34: ok | M34: 1 | N34: 3 | O34: 0 | P34: 0
A35: common_voice_ur_31784930.wav | B35: شادی ہوتی ہے۔ | C35: shadi hoti hai. | D35: शादी होती है। | E35: shadi hoti hai. | G35: =IFERROR(ROUND(M35/N35*100,2),0) | H35: =IFERROR(ROUND(O35/P35*100,2),0) | K35: 2.66 | L35: ok | M35: 3 | N35: 3 | O35: 0 | P35: 0
A36: common_voice_ur_31784931.wav | B36: کہ آخر زمین کا درجہ حرارت بڑھنے کے اس عمل کو | C36: ke aakhar zamin ka darja hraarat barhane ke is mal ko | D36: के आखिर जमीन का तरजीह गर्मारत बढ़ने के इस अंबल को | E36: ke akhir jameen ka tarajeeh garmaarat barhne ke is anbal ko | G36: =IFERROR(ROUND(M36/N36*100,2),0) | H36: =IFERROR(ROUND(O36/P36*100,2),0) | I36: jameen, tarajeeh, anbal | K36: 4.98 | L36: ok | M36: 8 | N36: 11 | O36: 0 | P36: 0
A37: common_voice_ur_31784942.wav | B37: جو امریکہ کہتاتھا وہی ٹھیک ٹھہرتا۔ | C37: jo amarika kahtaatha ohi theek thahrata. | D37: जो अमेरिका कहता था वही ठीक ठहरता। | E37: jo America kahta tha wahi theek thaharta. | G37: =IFERROR(ROUND(M37/N37*100,2),0) | H37: =IFERROR(ROUND(O37/P37*100,2),0) | I37: tha, wahi | K37: 3.37 | L37: ok | M37: 5 | N37: 6 | O37: 0 | P37: 0
A38: common_voice_ur_31784945.wav | B38: روح کی غذا اللہ کا ذکر ہے | C38: roh ki ghaza alla ka zakar hai | D38: रू की वजह लाका जिकर है। | E38: roo ki wajah laka jikar hai. | G38: =IFERROR(ROUND(M38/N38*100,2),0) | H38: =IFERROR(ROUND(O38/P38*100,2),0) | I38: roo, wajah, laka, jikar | K38: 8.04 | L38: ok | M38: 2 | N38: 7 | O38: 0 | P38: 0
A39: common_voice_ur_31784946.wav | B39: تو ان چہروں کی وجہ سے۔ | C39: to in chaharon ki wajah se. | D39: तो इन चेहरों की वजह से | E39: to in cheharon ki wajah se | G39: =IFERROR(ROUND(M39/N39*100,2),0) | H39: =IFERROR(ROUND(O39/P39*100,2),0) | K39: 3.02 | L39: ok | M39: 6 | N39: 6 | O39: 0 | P39: 0
A40: common_voice_ur_31789217.wav | B40: سیاسی جماعتیں بھی دانستہ اس کلچرکو فروغ دیتی ہیں۔ | C40: siaasi jmaatin bhi daansata is kalcharako farogh diti hain. | D40: सेवासी जमातें भी दानिस्ता इस कल्चर को फर्क देती हैं। | E40: sewasi jamaaten bhi daanista is culture ko phark deti hain. | G40: =IFERROR(ROUND(M40/N40*100,2),0) | H40: =IFERROR(ROUND(O40/P40*100,2),0) | I40: sewasi, culture, ko, phark | K40: 3.87 | L40: ok | M40: 6 | N40: 9 | O40: 0 | P40: 0
...
